[2022-11-11T06:53:30.355+0000] {taskinstance.py:1165} INFO - Dependencies all met for <TaskInstance: twitter_dag.etl manual__2022-11-11T06:53:29.319827+00:00 [queued]>
[2022-11-11T06:53:30.362+0000] {taskinstance.py:1165} INFO - Dependencies all met for <TaskInstance: twitter_dag.etl manual__2022-11-11T06:53:29.319827+00:00 [queued]>
[2022-11-11T06:53:30.363+0000] {taskinstance.py:1362} INFO - 
--------------------------------------------------------------------------------
[2022-11-11T06:53:30.364+0000] {taskinstance.py:1363} INFO - Starting attempt 1 of 1
[2022-11-11T06:53:30.366+0000] {taskinstance.py:1364} INFO - 
--------------------------------------------------------------------------------
[2022-11-11T06:53:30.375+0000] {taskinstance.py:1383} INFO - Executing <Task(PythonOperator): etl> on 2022-11-11 06:53:29.319827+00:00
[2022-11-11T06:53:30.382+0000] {standard_task_runner.py:55} INFO - Started process 398 to run task
[2022-11-11T06:53:30.387+0000] {standard_task_runner.py:82} INFO - Running: ['***', 'tasks', 'run', 'twitter_dag', 'etl', 'manual__2022-11-11T06:53:29.319827+00:00', '--job-id', '11', '--raw', '--subdir', 'DAGS_FOLDER/twitter_dag.py', '--cfg-path', '/tmp/tmpsnu2sgpp']
[2022-11-11T06:53:30.391+0000] {standard_task_runner.py:83} INFO - Job 11: Subtask etl
[2022-11-11T06:53:30.467+0000] {task_command.py:376} INFO - Running <TaskInstance: twitter_dag.etl manual__2022-11-11T06:53:29.319827+00:00 [running]> on host a428794d5959
[2022-11-11T06:53:30.536+0000] {taskinstance.py:1592} INFO - Exporting the following env vars:
AIRFLOW_CTX_DAG_OWNER=***
AIRFLOW_CTX_DAG_ID=twitter_dag
AIRFLOW_CTX_TASK_ID=etl
AIRFLOW_CTX_EXECUTION_DATE=2022-11-11T06:53:29.319827+00:00
AIRFLOW_CTX_TRY_NUMBER=1
AIRFLOW_CTX_DAG_RUN_ID=manual__2022-11-11T06:53:29.319827+00:00
[2022-11-11T06:53:31.958+0000] {taskinstance.py:1851} ERROR - Task failed with exception
Traceback (most recent call last):
  File "/home/airflow/.local/lib/python3.7/site-packages/airflow/operators/python.py", line 175, in execute
    return_value = self.execute_callable()
  File "/home/airflow/.local/lib/python3.7/site-packages/airflow/operators/python.py", line 193, in execute_callable
    return self.python_callable(*self.op_args, **self.op_kwargs)
  File "/opt/airflow/dags/twitter_etl.py", line 34, in etl
    with s3.open(file_name, 'w') as f:
  File "/home/airflow/.local/lib/python3.7/site-packages/fsspec/spec.py", line 1100, in open
    **kwargs,
  File "/home/airflow/.local/lib/python3.7/site-packages/fsspec/spec.py", line 1112, in open
    **kwargs,
  File "/home/airflow/.local/lib/python3.7/site-packages/s3fs/core.py", line 652, in _open
    cache_options=cache_options,
  File "/home/airflow/.local/lib/python3.7/site-packages/s3fs/core.py", line 1962, in __init__
    raise ValueError("Attempt to open non key-like path: %s" % path)
ValueError: Attempt to open non key-like path: user_tweets_20221111.csv
[2022-11-11T06:53:31.991+0000] {taskinstance.py:1406} INFO - Marking task as FAILED. dag_id=twitter_dag, task_id=etl, execution_date=20221111T065329, start_date=20221111T065330, end_date=20221111T065331
[2022-11-11T06:53:32.004+0000] {standard_task_runner.py:105} ERROR - Failed to execute job 11 for task etl (Attempt to open non key-like path: user_tweets_20221111.csv; 398)
[2022-11-11T06:53:32.026+0000] {local_task_job.py:164} INFO - Task exited with return code 1
[2022-11-11T06:53:32.045+0000] {local_task_job.py:273} INFO - 0 downstream tasks scheduled from follow-on schedule check
