[2022-11-11T06:51:09.747+0000] {taskinstance.py:1165} INFO - Dependencies all met for <TaskInstance: twitter_dag.etl manual__2022-11-11T06:51:08.370755+00:00 [queued]>
[2022-11-11T06:51:09.754+0000] {taskinstance.py:1165} INFO - Dependencies all met for <TaskInstance: twitter_dag.etl manual__2022-11-11T06:51:08.370755+00:00 [queued]>
[2022-11-11T06:51:09.756+0000] {taskinstance.py:1362} INFO - 
--------------------------------------------------------------------------------
[2022-11-11T06:51:09.757+0000] {taskinstance.py:1363} INFO - Starting attempt 1 of 1
[2022-11-11T06:51:09.758+0000] {taskinstance.py:1364} INFO - 
--------------------------------------------------------------------------------
[2022-11-11T06:51:09.767+0000] {taskinstance.py:1383} INFO - Executing <Task(PythonOperator): etl> on 2022-11-11 06:51:08.370755+00:00
[2022-11-11T06:51:09.774+0000] {standard_task_runner.py:55} INFO - Started process 277 to run task
[2022-11-11T06:51:09.778+0000] {standard_task_runner.py:82} INFO - Running: ['***', 'tasks', 'run', 'twitter_dag', 'etl', 'manual__2022-11-11T06:51:08.370755+00:00', '--job-id', '9', '--raw', '--subdir', 'DAGS_FOLDER/twitter_dag.py', '--cfg-path', '/tmp/tmp2ob0foq6']
[2022-11-11T06:51:09.781+0000] {standard_task_runner.py:83} INFO - Job 9: Subtask etl
[2022-11-11T06:51:09.855+0000] {task_command.py:376} INFO - Running <TaskInstance: twitter_dag.etl manual__2022-11-11T06:51:08.370755+00:00 [running]> on host a428794d5959
[2022-11-11T06:51:09.916+0000] {taskinstance.py:1592} INFO - Exporting the following env vars:
AIRFLOW_CTX_DAG_OWNER=***
AIRFLOW_CTX_DAG_ID=twitter_dag
AIRFLOW_CTX_TASK_ID=etl
AIRFLOW_CTX_EXECUTION_DATE=2022-11-11T06:51:08.370755+00:00
AIRFLOW_CTX_TRY_NUMBER=1
AIRFLOW_CTX_DAG_RUN_ID=manual__2022-11-11T06:51:08.370755+00:00
[2022-11-11T06:51:10.654+0000] {taskinstance.py:1851} ERROR - Task failed with exception
Traceback (most recent call last):
  File "/home/airflow/.local/lib/python3.7/site-packages/airflow/operators/python.py", line 175, in execute
    return_value = self.execute_callable()
  File "/home/airflow/.local/lib/python3.7/site-packages/airflow/operators/python.py", line 193, in execute_callable
    return self.python_callable(*self.op_args, **self.op_kwargs)
  File "/opt/airflow/dags/twitter_etl.py", line 33, in etl
    file_name = 'user_tweets_{date}.csv'.format(datetime.today().strftime('%Y%m%d'))
KeyError: 'date'
[2022-11-11T06:51:10.679+0000] {taskinstance.py:1406} INFO - Marking task as FAILED. dag_id=twitter_dag, task_id=etl, execution_date=20221111T065108, start_date=20221111T065109, end_date=20221111T065110
[2022-11-11T06:51:10.699+0000] {standard_task_runner.py:105} ERROR - Failed to execute job 9 for task etl ('date'; 277)
[2022-11-11T06:51:10.745+0000] {local_task_job.py:164} INFO - Task exited with return code 1
[2022-11-11T06:51:10.765+0000] {local_task_job.py:273} INFO - 0 downstream tasks scheduled from follow-on schedule check
