[2022-11-11T06:52:29.559+0000] {taskinstance.py:1165} INFO - Dependencies all met for <TaskInstance: twitter_dag.etl manual__2022-11-11T06:52:28.157203+00:00 [queued]>
[2022-11-11T06:52:29.567+0000] {taskinstance.py:1165} INFO - Dependencies all met for <TaskInstance: twitter_dag.etl manual__2022-11-11T06:52:28.157203+00:00 [queued]>
[2022-11-11T06:52:29.568+0000] {taskinstance.py:1362} INFO - 
--------------------------------------------------------------------------------
[2022-11-11T06:52:29.570+0000] {taskinstance.py:1363} INFO - Starting attempt 1 of 1
[2022-11-11T06:52:29.571+0000] {taskinstance.py:1364} INFO - 
--------------------------------------------------------------------------------
[2022-11-11T06:52:29.580+0000] {taskinstance.py:1383} INFO - Executing <Task(PythonOperator): etl> on 2022-11-11 06:52:28.157203+00:00
[2022-11-11T06:52:29.587+0000] {standard_task_runner.py:55} INFO - Started process 351 to run task
[2022-11-11T06:52:29.592+0000] {standard_task_runner.py:82} INFO - Running: ['***', 'tasks', 'run', 'twitter_dag', 'etl', 'manual__2022-11-11T06:52:28.157203+00:00', '--job-id', '10', '--raw', '--subdir', 'DAGS_FOLDER/twitter_dag.py', '--cfg-path', '/tmp/tmp3mahx44x']
[2022-11-11T06:52:29.595+0000] {standard_task_runner.py:83} INFO - Job 10: Subtask etl
[2022-11-11T06:52:29.664+0000] {task_command.py:376} INFO - Running <TaskInstance: twitter_dag.etl manual__2022-11-11T06:52:28.157203+00:00 [running]> on host a428794d5959
[2022-11-11T06:52:29.723+0000] {taskinstance.py:1592} INFO - Exporting the following env vars:
AIRFLOW_CTX_DAG_OWNER=***
AIRFLOW_CTX_DAG_ID=twitter_dag
AIRFLOW_CTX_TASK_ID=etl
AIRFLOW_CTX_EXECUTION_DATE=2022-11-11T06:52:28.157203+00:00
AIRFLOW_CTX_TRY_NUMBER=1
AIRFLOW_CTX_DAG_RUN_ID=manual__2022-11-11T06:52:28.157203+00:00
[2022-11-11T06:52:30.790+0000] {taskinstance.py:1851} ERROR - Task failed with exception
Traceback (most recent call last):
  File "/home/airflow/.local/lib/python3.7/site-packages/airflow/operators/python.py", line 175, in execute
    return_value = self.execute_callable()
  File "/home/airflow/.local/lib/python3.7/site-packages/airflow/operators/python.py", line 193, in execute_callable
    return self.python_callable(*self.op_args, **self.op_kwargs)
  File "/opt/airflow/dags/twitter_etl.py", line 34, in etl
    with s3.open(file_name, 'w') as f:
  File "/home/airflow/.local/lib/python3.7/site-packages/fsspec/spec.py", line 1100, in open
    **kwargs,
  File "/home/airflow/.local/lib/python3.7/site-packages/fsspec/spec.py", line 1112, in open
    **kwargs,
  File "/home/airflow/.local/lib/python3.7/site-packages/s3fs/core.py", line 652, in _open
    cache_options=cache_options,
  File "/home/airflow/.local/lib/python3.7/site-packages/s3fs/core.py", line 1962, in __init__
    raise ValueError("Attempt to open non key-like path: %s" % path)
ValueError: Attempt to open non key-like path: user_tweets_20221111.csv
[2022-11-11T06:52:30.819+0000] {taskinstance.py:1406} INFO - Marking task as FAILED. dag_id=twitter_dag, task_id=etl, execution_date=20221111T065228, start_date=20221111T065229, end_date=20221111T065230
[2022-11-11T06:52:30.832+0000] {standard_task_runner.py:105} ERROR - Failed to execute job 10 for task etl (Attempt to open non key-like path: user_tweets_20221111.csv; 351)
[2022-11-11T06:52:30.862+0000] {local_task_job.py:164} INFO - Task exited with return code 1
[2022-11-11T06:52:30.880+0000] {local_task_job.py:273} INFO - 0 downstream tasks scheduled from follow-on schedule check
