[2022-11-11T06:59:21.760+0000] {taskinstance.py:1165} INFO - Dependencies all met for <TaskInstance: twitter_dag.etl manual__2022-11-11T06:59:20.476838+00:00 [queued]>
[2022-11-11T06:59:21.768+0000] {taskinstance.py:1165} INFO - Dependencies all met for <TaskInstance: twitter_dag.etl manual__2022-11-11T06:59:20.476838+00:00 [queued]>
[2022-11-11T06:59:21.769+0000] {taskinstance.py:1362} INFO - 
--------------------------------------------------------------------------------
[2022-11-11T06:59:21.770+0000] {taskinstance.py:1363} INFO - Starting attempt 1 of 1
[2022-11-11T06:59:21.772+0000] {taskinstance.py:1364} INFO - 
--------------------------------------------------------------------------------
[2022-11-11T06:59:21.781+0000] {taskinstance.py:1383} INFO - Executing <Task(PythonOperator): etl> on 2022-11-11 06:59:20.476838+00:00
[2022-11-11T06:59:21.787+0000] {standard_task_runner.py:55} INFO - Started process 694 to run task
[2022-11-11T06:59:21.792+0000] {standard_task_runner.py:82} INFO - Running: ['***', 'tasks', 'run', 'twitter_dag', 'etl', 'manual__2022-11-11T06:59:20.476838+00:00', '--job-id', '12', '--raw', '--subdir', 'DAGS_FOLDER/twitter_dag.py', '--cfg-path', '/tmp/tmp2lw3d0c2']
[2022-11-11T06:59:21.795+0000] {standard_task_runner.py:83} INFO - Job 12: Subtask etl
[2022-11-11T06:59:21.860+0000] {task_command.py:376} INFO - Running <TaskInstance: twitter_dag.etl manual__2022-11-11T06:59:20.476838+00:00 [running]> on host a428794d5959
[2022-11-11T06:59:21.918+0000] {taskinstance.py:1592} INFO - Exporting the following env vars:
AIRFLOW_CTX_DAG_OWNER=***
AIRFLOW_CTX_DAG_ID=twitter_dag
AIRFLOW_CTX_TASK_ID=etl
AIRFLOW_CTX_EXECUTION_DATE=2022-11-11T06:59:20.476838+00:00
AIRFLOW_CTX_TRY_NUMBER=1
AIRFLOW_CTX_DAG_RUN_ID=manual__2022-11-11T06:59:20.476838+00:00
[2022-11-11T06:59:22.604+0000] {taskinstance.py:1851} ERROR - Task failed with exception
Traceback (most recent call last):
  File "/home/airflow/.local/lib/python3.7/site-packages/airflow/operators/python.py", line 175, in execute
    return_value = self.execute_callable()
  File "/home/airflow/.local/lib/python3.7/site-packages/airflow/operators/python.py", line 193, in execute_callable
    return self.python_callable(*self.op_args, **self.op_kwargs)
  File "/opt/airflow/dags/twitter_etl.py", line 34, in etl
    df.to_csv(file_name)
  File "/home/airflow/.local/lib/python3.7/site-packages/pandas/core/generic.py", line 3482, in to_csv
    storage_options=storage_options,
  File "/home/airflow/.local/lib/python3.7/site-packages/pandas/io/formats/format.py", line 1105, in to_csv
    csv_formatter.save()
  File "/home/airflow/.local/lib/python3.7/site-packages/pandas/io/formats/csvs.py", line 243, in save
    storage_options=self.storage_options,
  File "/home/airflow/.local/lib/python3.7/site-packages/pandas/io/common.py", line 614, in get_handle
    storage_options=storage_options,
  File "/home/airflow/.local/lib/python3.7/site-packages/pandas/io/common.py", line 359, in _get_filepath_or_buffer
    filepath_or_buffer, mode=fsspec_mode, **(storage_options or {})
  File "/home/airflow/.local/lib/python3.7/site-packages/fsspec/core.py", line 450, in open
    **kwargs,
  File "/home/airflow/.local/lib/python3.7/site-packages/fsspec/core.py", line 284, in open_files
    [fs.makedirs(parent, exist_ok=True) for parent in parents]
  File "/home/airflow/.local/lib/python3.7/site-packages/fsspec/core.py", line 284, in <listcomp>
    [fs.makedirs(parent, exist_ok=True) for parent in parents]
  File "/home/airflow/.local/lib/python3.7/site-packages/fsspec/asyn.py", line 113, in wrapper
    return sync(self.loop, func, *args, **kwargs)
  File "/home/airflow/.local/lib/python3.7/site-packages/fsspec/asyn.py", line 98, in sync
    raise return_result
  File "/home/airflow/.local/lib/python3.7/site-packages/fsspec/asyn.py", line 53, in _runner
    result[0] = await coro
  File "/home/airflow/.local/lib/python3.7/site-packages/s3fs/core.py", line 855, in _makedirs
    await self._mkdir(path, create_parents=True)
  File "/home/airflow/.local/lib/python3.7/site-packages/s3fs/core.py", line 821, in _mkdir
    raise ValueError
ValueError
[2022-11-11T06:59:22.628+0000] {taskinstance.py:1406} INFO - Marking task as FAILED. dag_id=twitter_dag, task_id=etl, execution_date=20221111T065920, start_date=20221111T065921, end_date=20221111T065922
[2022-11-11T06:59:22.645+0000] {standard_task_runner.py:105} ERROR - Failed to execute job 12 for task etl (; 694)
[2022-11-11T06:59:22.695+0000] {local_task_job.py:164} INFO - Task exited with return code 1
[2022-11-11T06:59:22.713+0000] {local_task_job.py:273} INFO - 0 downstream tasks scheduled from follow-on schedule check
